Workbook

Sheet Исходные данные
A1: Общая инфорамция
A2: № Приказа об утверждении ГЭК | B2: 1156 о.д. от 15.12.2023
A3: Наименование кафедры (полностью) | B3: Кафедра "Наименование кафедры"
A4: Количество студентов обучающихся на бюджетной основе допущенных к ГЭК | B4: 5
A5: Количество студентов обучающихся на платной основе допущенных к ГЭК | B5: 5
A6: Ф.И.О заведующего кафедров | B6: Верещагин С.Б.
A7: Контактный номер телефона заведующего кафедрой | B7: 8(499)155-08-20
A8: Контактный адрес электронной почты заведующего кафедрой | B8: tws@madi.ru
A9: Информация о рецензенте
A10: Ф.И.О (полностью) Рецензента | B10: Амосов Алексей Германович

Sheet Расчёт стомости
A1: Расчет стоимости оказания образовательных услуг сторонних лиц, не являющихся работниками МАДИ
D2: Факультет "Дорожные и технологические машины"
A3: ФИО | B3: Должность в ГЭК | C3: Стоимость часа, руб. | D3: Норма времени на 1 студента, час. | E3: Всего студентов, чел. | F3: из них | H3: Всего часов | I3: Всего к оплате, в руб. | K3: из них | M3: Итого с учетом ЕНП, в руб. | N3: из них
F4: бюджет | G4: платное | J4: в том числе НДФЛ, 13% | K4: бюджет | L4: платное | N4: бюджет | O4: платное
A5: 1 | B5: 2 | C5: 3 | D5: 4 | E5: 5 (6+7) | F5: 6 | G5: 7 | H5: 8 | I5: 9 | J5: 10 | K5: 11 | L5: 12 | M5: 13 | N5: 14 | O5: 15
A6: Панченко Александр Сергеевич | B6: Рецензент ВКР | C6: 590 | D6: 2 | E6: =F6+G6 -> 49 | F6: 0 | G6: 49 | H6: =E6*D6 -> 98 | I6: =H6*C6 -> 57820 | J6: =I6*13% -> 7516.6 | K6: =C6*D6*F6 -> 0 | L6: =C6*D6*G6 -> 57820 | M6: =I6*1.3 -> 75166 | N6: =K6*1.3 -> 0 | O6: =L6*1.3 -> 75166
A7: Итого | H7: =SUM(H6:H6) -> 98 | I7: =SUM(I6:I6) -> 57820 | J7: =SUM(J6:J6) -> 7516.6 | K7: =SUM(K6:K6) -> 0 | L7: =SUM(L6:L6) -> 57820 | M7: =SUM(M6:M6) -> 75166 | N7: =SUM(N6:N6) -> 0 | O7: =SUM(O6:O6) -> 75166
A9: ='Исходные данные'!B3 -> Кафедра "Наименование кафедры" | F9: ='Исходные данные'!B6 -> Верещагин С.Б.
A11: СОГЛАСОВАНО:
A13: Первый проректор - проректор по образовательной деятельности | F13: Артемьев И.А.

Sheet Заявка на закупку
AA1: Приложение № 1
AA2: к приказу от «12» января 2018 г. № 9 о.д.
AA4: УТВЕРЖДАЮ
A5: Справочно:
A6: Передано в КС МАДИ | AA6: должность
A7: Включено в план закупок
A8: Включено в план-график | AA8: подпись И.О.Фамилия
A9: Опубликовано извещение | AA9: «____»_____________ 20__ г.
A11: З А Я В К А Н А З А К У П К У
A12: №_______ от «_____»____________ 20___ г.
A14: 1) Прошу Вас для нужд | G14: ='Исходные данные'!B3 -> Кафедра "Наименование кафедры"
A15: наименование структурного подразделения
A16: провести закупку следующих товаров (работ, услуг):
A17: ='[1]Ввод данных'!A2 -> № п/п | C17: Наименование товара (работ, услуг) | Y17: Кол-во товара (работ, услуг) | AC17: Цена за единицу товара (работ, услуг) | AG17: Стоимость, руб.
A18: 1 | C18: ="Оказание образовательных услуг сторонним лицом, не являющимся работником МАДИ, в качестве рецензента выпускных квалификационных работ - "&'Исходные данные'!B10 -> Оказание образовательных услуг сторонним лицом, не являющимся работником МАДИ, в качестве рецензента выпускных квалификационных работ - Амосов Алексей Германович | Y18: 118 | AC18: ='Расчёт стомости'!C6 -> 590 | AG18: ='Расчёт стомости'!M7 -> 75166
A19: ='[1]Ввод данных'!A6 -> 0 | C19: ='[1]Ввод данных'!B6 -> 0 | Y19: =CONCATENATE('[1]Ввод данных'!F6," ",'[1]Ввод данных'!G6) | AC19: ='[1]Ввод данных'!I6 -> 0 | AG19: ='[1]Ввод данных'!J6 -> 0
A20: ='[1]Ввод данных'!A7 -> 0 | C20: ='[1]Ввод данных'!B7 -> 0 | Y20: =CONCATENATE('[1]Ввод данных'!F7," ",'[1]Ввод данных'!G7) | AC20: ='[1]Ввод данных'!I7 -> 0 | AG20: ='[1]Ввод данных'!J7 -> 0
A21: ='[1]Ввод данных'!A8 -> 0 | C21: ='[1]Ввод данных'!B8 -> 0 | Y21: =CONCATENATE('[1]Ввод данных'!F8," ",'[1]Ввод данных'!G8) | AC21: ='[1]Ввод данных'!I8 -> 0 | AG21: ='[1]Ввод данных'!J8 -> 0
A22: ='[1]Ввод данных'!A9 -> 0 | C22: ='[1]Ввод данных'!B9 -> 0 | Y22: =CONCATENATE('[1]Ввод данных'!F9," ",'[1]Ввод данных'!G9) | AC22: ='[1]Ввод данных'!I9 -> 0 | AG22: ='[1]Ввод данных'!J9 -> 0
A23: ='[1]Ввод данных'!A10 -> 0 | C23: ='[1]Ввод данных'!B10 -> 0 | Y23: =CONCATENATE('[1]Ввод данных'!F10," ",'[1]Ввод данных'!G10) | AC23: ='[1]Ввод данных'!I10 -> 0 | AG23: ='[1]Ввод данных'!J10 -> 0
A24: ='[1]Ввод данных'!A11 -> 0 | C24: ='[1]Ввод данных'!B11 -> 0 | Y24: =CONCATENATE('[1]Ввод данных'!F11," ",'[1]Ввод данных'!G11) | AC24: ='[1]Ввод данных'!I11 -> 0 | AG24: ='[1]Ввод данных'!J11 -> 0
A25: ='[1]Ввод данных'!A12 -> 0 | C25: ='[1]Ввод данных'!B12 -> 0 | Y25: =CONCATENATE('[1]Ввод данных'!F12," ",'[1]Ввод данных'!G12) | AC25: ='[1]Ввод данных'!I12 -> 0 | AG25: ='[1]Ввод данных'!J12 -> 0
A26: ='[1]Ввод данных'!A13 -> 0 | C26: ='[1]Ввод данных'!B13 -> 0 | Y26: =CONCATENATE('[1]Ввод данных'!F13," ",'[1]Ввод данных'!G13) | AC26: ='[1]Ввод данных'!I13 -> 0 | AG26: ='[1]Ввод данных'!J13 -> 0
A27: ='[1]Ввод данных'!A14 -> 0 | C27: ='[1]Ввод данных'!B14 -> 0 | Y27: =CONCATENATE('[1]Ввод данных'!F14," ",'[1]Ввод данных'!G14) | AC27: ='[1]Ввод данных'!I14 -> 0 | AG27: ='[1]Ввод данных'!J14 -> 0
A28: ='[1]Ввод данных'!A15 -> 0 | C28: ='[1]Ввод данных'!B15 -> 0 | Y28: =CONCATENATE('[1]Ввод данных'!F15," ",'[1]Ввод данных'!G15) | AC28: ='[1]Ввод данных'!I15 -> 0 | AG28: ='[1]Ввод данных'!J15 -> 0
A29: ='[1]Ввод данных'!A16 -> 0 | C29: ='[1]Ввод данных'!B16 -> 0 | Y29: =CONCATENATE('[1]Ввод данных'!F16," ",'[1]Ввод данных'!G16) | AC29: ='[1]Ввод данных'!I16 -> 0 | AG29: ='[1]Ввод данных'!J16 -> 0
A30: ='[1]Ввод данных'!A17 -> 0 | C30: ='[1]Ввод данных'!B17 -> 0 | Y30: =CONCATENATE('[1]Ввод данных'!F17," ",'[1]Ввод данных'!G17) | AC30: ='[1]Ввод данных'!I17 -> 0 | AG30: ='[1]Ввод данных'!J17 -> 0
... A115: ='[1]Ввод данных'!A102 -> 0 | C115: ='[1]Ввод данных'!B102 -> 0 | Y115: =CONCATENATE('[1]Ввод данных'!F102," ",'[1]Ввод данных'!G102) | AC115: ='[1]Ввод данных'!I102 -> 0 | AG115: ='[1]Ввод данных'!J102 -> 0
A116: ='[1]Ввод данных'!A103 -> 0 | C116: ='[1]Ввод данных'!B103 -> 0 | Y116: =CONCATENATE('[1]Ввод данных'!F103," ",'[1]Ввод данных'!G103) | AC116: ='[1]Ввод данных'!I103 -> 0 | AG116: 1
A117: Итого на сумму: | AG117: =AG18 -> 75166
A118: Техническое задание и обоснование цены на | N118: листах прилагаются.
A120: Ответственное структурное подразделение: | L120: ='Исходные данные'!B3 -> Кафедра "Наименование кафедры"
A121: и лицо от подразделения:
A122: при проведении закупки, в том числе и в комиссии | S122: при приёмке и оплате товара (работ, услуг)
A123: Фамилия, Имя, Отчество | H123: ='Исходные данные'!B6 -> Верещагин С.Б. | S123: Фамилия, Имя, Отчество | Z123: ='Исходные данные'!B6 -> Верещагин С.Б.
A124: Должность | H124: заведующий кафедрой | S124: Должность | Z124: заведующий кафедрой
A125: Телефон | H125: ='Исходные данные'!B7 -> 8(499)155-08-20 | S125: Телефон | Z125: ='Исходные данные'!B7 -> 8(499)155-08-20
A126: E-mail | H126: ='Исходные данные'!B8 -> tws@madi.ru | S126: E-mail | Z126: ='Исходные данные'!B8 -> tws@madi.ru
A127: Подпись ответственного лица | S127: Подпись ответственного лица
A129: Руководитель подразделения: | I129: ='Исходные данные'!B6 -> Верещагин С.Б. | AA129: «_____» ___________20____ г.
...

Sheet Служебная записка
A1: Московский автомобильно-дорожный | F1: Первому проректору - проректору по образовательной деятельности Артемьеву И.А.
A2: государственный технический
A3: университет (МАДИ)
A7: ='Исходные данные'!B3 -> Кафедра "Наименование кафедры"
A9: =TODAY() -> 45769
A12: Служебная записка
A14: В целях проведения государственной итоговой аттестации прошу Вас согласовать заявку на приобретение следующих услуг:
A18: 1. | B18: ='Заявка на закупку'!C18&", количество часов - "&'Расчёт стомости'!H6&", стоимость оказываемых услуг - "&'Расчёт стомости'!M6& " рублей, в том числе ЕНП " &'Расчёт стомости'!M6-'Расчёт стомости'!I6 &" рублей" -> Оказание образовательных услуг сторонним лицом, не являющимся работником МАДИ, в качестве рецензента выпускных квалификационных работ - Амосов Алексей Германович, количество часов - 98, стоимость оказываемых услуг - 75166 рублей, в том числе ЕНП 17346 рублей
A24: =" Общая стоимость приобретаемых услуг составит "& 'Расчёт стомости'!M7&" рублей, в том числе ЕНП - " &'Расчёт стомости'!M7-'Расчёт стомости'!I7 & " рублей" -> Общая стоимость приобретаемых услуг составит 75166 рублей, в том числе ЕНП - 17346 рублей
A27: Заведующий кафедрой | G27: ='Исходные данные'!B6 -> Верещагин С.Б.
